Workbook

Sheet Resumen
A1: Licita – Resumen del modelo financiero: Base vs Conservador
A2: Cifras en CLP sin IVA. Edite supuestos en 'Supuestos' y 'Escenarios'; esta hoja se actualiza sola.
A4: Estado de resultados | B4: Base Año 1 | C4: Base Año 2 | D4: Conservador Año 1 | E4: Conservador Año 2 | F4: Diferencia 24 meses (Cons. − Base)
A5: Ingresos netos | B5: =SUM('Proyección Base'!C22:N22) -> 29048799 | C5: =SUM('Proyección Base'!O22:Z22) -> 1.6713456e+08 | D5: =SUM('Proyección Conservador'!C22:N22) -> 10745136 | E5: =SUM('Proyección Conservador'!O22:Z22) -> 41724688 | F5: =(D5+E5)-(B5+C5) -> -1.4371354e+08
A6: Costos variables | B6: =SUM('Proyección Base'!C28:N28) -> 5721836.5 | C6: =SUM('Proyección Base'!O28:Z28) -> 32304027 | D6: =SUM('Proyección Conservador'!C28:N28) -> 2046390.6 | E6: =SUM('Proyección Conservador'!O28:Z28) -> 7946386.6 | F6: =(D6+E6)-(B6+C6) -> -28033086
A7: Margen de contribución | B7: =SUM('Proyección Base'!C29:N29) -> 23326963 | C7: =SUM('Proyección Base'!O29:Z29) -> 1.3483054e+08 | D7: =SUM('Proyección Conservador'!C29:N29) -> 8698745.7 | E7: =SUM('Proyección Conservador'!O29:Z29) -> 33778301 | F7: =(D7+E7)-(B7+C7) -> -1.1568045e+08
A8: Costos fijos y de estructura | B8: =SUM('Proyección Base'!C40:N40) -> 20715397 | C8: =SUM('Proyección Base'!O40:Z40) -> 49693793 | D8: =SUM('Proyección Conservador'!C40:N40) -> 18071065 | E8: =SUM('Proyección Conservador'!O40:Z40) -> 33000986 | F8: =(D8+E8)-(B8+C8) -> -19337139
A9: EBITDA | B9: =SUM('Proyección Base'!C43:N43) -> 2611565.5 | C9: =SUM('Proyección Base'!O43:Z43) -> 85136742 | D9: =SUM('Proyección Conservador'!C43:N43) -> -9372319.6 | E9: =SUM('Proyección Conservador'!O43:Z43) -> 777315.18 | F9: =(D9+E9)-(B9+C9) -> -96343312
A10: Resultado antes de impuestos | B10: =SUM('Proyección Base'!C45:N45) -> 2011565.5 | C10: =SUM('Proyección Base'!O45:Z45) -> 84536742 | D10: =SUM('Proyección Conservador'!C45:N45) -> -9972319.6 | E10: =SUM('Proyección Conservador'!O45:Z45) -> 177315.18 | F10: =(D10+E10)-(B10+C10) -> -96343312
A11: Margen de contribución % | B11: =IF(B5=0,0,B7/B5) -> 0.80302675 | C11: =IF(C5=0,0,C7/C5) -> 0.80671845 | D11: =IF(D5=0,0,D7/D5) -> 0.80955192 | E11: =IF(E5=0,0,E7/E5) -> 0.80955192
A13: Indicador clave | B13: Base | C13: Conservador | G13: Nota
A14: Clientes activos al mes 12 | B14: ='Proyección Base'!N9 -> 205.20414 | C14: ='Proyección Conservador'!N9 -> 72.937493
A15: Clientes activos al mes 24 | B15: ='Proyección Base'!Z9 -> 925.20098 | C15: ='Proyección Conservador'!Z9 -> 218.38145
A16: MRR neto al mes 12 | B16: ='Proyección Base'!N22 -> 5378040.5 | C16: ='Proyección Conservador'!N22 -> 1786305.4 | G16: Ingreso mensual recurrente sin IVA.
A17: MRR neto al mes 24 | B17: ='Proyección Base'!Z22 -> 25641411 | C17: ='Proyección Conservador'!Z22 -> 5348359.9
A18: ARR al mes 24 | B18: ='Proyección Base'!Z49 -> 3.0769693e+08 | C18: ='Proyección Conservador'!Z49 -> 64180319
A19: Contribución promedio por cliente (mes 24) | B19: ='Proyección Base'!Z51 -> 22489.366 | C19: ='Proyección Conservador'!Z51 -> 19826.661
A20: Primer mes con EBITDA ≥ 0 | B20: =IFERROR(MATCH(1,'Proyección Base'!C52:Z52,0),"No en 24 meses") -> 4 | C20: =IFERROR(MATCH(1,'Proyección Conservador'!C52:Z52,0),"No en 24 meses") -> 19 | G20: Puede volver a negativo cuando empiezan los sueldos; ver 'Meses con EBITDA negativo'.
A21: Meses con EBITDA negativo (de 24) | B21: =24-SUM('Proyección Base'!C52:Z52) -> 5 | C21: =24-SUM('Proyección Conservador'!C52:Z52) -> 18
A22: Pérdida acumulada máxima (necesidad de caja aprox.) | B22: =MIN(0,MIN('Proyección Base'!C46:Z46)) -> -1401902.2 | C22: =MIN(0,MIN('Proyección Conservador'!C46:Z46)) -> -13064174 | G22: Aproximación: no considera desfase de pagos anuales ni IVA.
A23: Resultado acumulado al mes 24 | B23: ='Proyección Base'!Z46 -> 86548308 | C23: ='Proyección Conservador'!Z46 -> -9795004.5
A24: Clientes para cubrir costos fijos de lanzamiento (sin sueldos ni marketing) | B24: =IF('Proyección Base'!Z51<=0,0,ROUNDUP((Supuestos!$B$72+Supuestos!$B$74+Supuestos!$B$81)/'Proyección Base'!Z51,0)) -> 17 | C24: =IF('Proyección Conservador'!Z51<=0,0,ROUNDUP((Supuestos!$B$72+Supuestos!$B$74+Supuestos!$B$81)/'Proyección Conservador'!Z51,0)) -> 19 | G24: Costo fijo de lanzamiento ÷ contribución promedio por cliente.
A26: Supuestos que cambian entre escenarios
A27: Nuevos clientes en el mes 1 | B27: =Escenarios!$B$5 -> 10 | C27: =Escenarios!$C$5 -> 5
A28: Crecimiento mensual de nuevos clientes | B28: =Escenarios!$B$6 -> 0.12 | C28: =Escenarios!$C$6 -> 0.08
A29: Fuga mensual (churn) | B29: =Escenarios!$B$7 -> 0.04 | C29: =Escenarios!$C$7 -> 0.06
A30: % Pro | B30: =Escenarios!$B$9 -> 0.2 | C30: =Escenarios!$C$9 -> 0.16
A31: % que paga anual | B31: =Escenarios!$B$11 -> 0.25 | C31: =Escenarios!$C$11 -> 0.15
A32: CAC | B32: =Escenarios!$B$12 -> 25000 | C32: =Escenarios!$C$12 -> 40000
A34: Advertencias
A35: • Modelo de resultados (devengado), no de caja: los pagos anuales entran por adelantado en caja.
A36: • No incluye impuesto a la renta. Consultar régimen tributario (Pro Pyme) con contador.
A37: • Tarifas de WhatsApp, pasarela, contador y servicios son estimaciones; cotizar antes de decidir.
A38: • Precios de la IA: lista oficial de Anthropic (sept-2026); el uso por cliente es una estimación a validar en el piloto.

Sheet Supuestos
A1: Licita – Modelo financiero: Supuestos
A2: Cómo usar: edite solo las celdas en AZUL con fondo amarillo (supuestos). Las celdas negras son fórmulas. Montos en CLP salvo que se indique USD.
A3: Colores: azul = dato de entrada · negro = fórmula · verde = vínculo a otra hoja.
A5: 1. General | B5: Valor | C5: Unidad | D5: Nota / fuente
A6: Tipo de cambio | B6: 950 | C6: CLP/USD | D6: Estimación oct-2026; actualizar con dólar observado (Banco Central).
A7: IVA | B7: 0.19 | C7: % | D7: Tasa IVA Chile.
A9: 2. Precios de lista (con IVA) | B9: Valor | C9: Unidad | D9: Nota / fuente
A10: Plan Pyme – mensual | B10: 19990 | C10: CLP/mes | D10: Definido en la conversación.
A11: Plan Pro – mensual | B11: 59990 | C11: CLP/mes | D11: Definido en la conversación.
A12: Plan Pro – precio fundador | B12: 39990 | C12: CLP/mes | D12: Precio congelado de por vida para los primeros clientes Pro.
A13: Cupos precio fundador | B13: 100 | C13: clientes | D13: Simplificación: los primeros N clientes Pro activos pagan precio fundador.
A14: Plan Consultoras – por empresa gestionada | B14: 29990 | C14: CLP/empresa/mes | D14: Mínimo 5 empresas.
A15: Empresas promedio por consultora | B15: 6 | C15: empresas
A16: Descuento pago anual | B16: 0.1 | C16: % | D16: Definido por el usuario: descuento pequeño.
A17: Precio anual Pyme (con IVA) | B17: =ROUND($B$10*12*(1-$B$16),-2)-10 -> 215890 | C17: CLP/año | D17: Ajustado a $215.890 para que el IVA calculado por el SII cuadre exacto.
A18: Precio anual Pro (con IVA) | B18: =ROUND($B$11*12*(1-$B$16),-2) -> 647900 | C18: CLP/año
A19: Precio anual Pro fundador (con IVA) | B19: =ROUND($B$12*12*(1-$B$16),-2) -> 431900 | C19: CLP/año
A20: Precio neto de lista Pyme (sin IVA) | B20: =$B$10/(1+$B$7) -> 16798.319 | C20: CLP/cliente/mes
A21: Precio neto de lista Pro (sin IVA) | B21: =$B$11/(1+$B$7) -> 50411.765 | C21: CLP/cliente/mes
A22: Precio neto de lista Pro fundador (sin IVA) | B22: =$B$12/(1+$B$7) -> 33605.042 | C22: CLP/cliente/mes
A23: Precio neto de lista Consultoras por empresa (sin IVA) | B23: =$B$14/(1+$B$7) -> 25201.681 | C23: CLP/empresa/mes
A25: 3. Crecimiento, mezcla de planes, pago anual y CAC | B25: Valor | C25: Unidad | D25: Nota / fuente
A26: Estos supuestos varían por escenario: edítelos en la hoja Escenarios.
A28: 4. Inteligencia artificial (API de Claude) | B28: Valor | C28: Unidad | D28: Nota / fuente
A29: Haiku 4.5 – entrada | B29: 1 | C29: USD/millón tokens | D29: Precio de lista Anthropic (sept-2026).
A30: Haiku 4.5 – salida | B30: 5 | C30: USD/millón tokens | D30: Precio de lista Anthropic (sept-2026).
A31: Sonnet 5.5 – entrada | B31: 2 | C31: USD/millón tokens | D31: Precio de lista Anthropic (sept-2026).
A32: Sonnet 5.5 – salida | B32: 10 | C32: USD/millón tokens | D32: Precio de lista Anthropic (sept-2026).
A33: Sonnet 5.5 – lectura de caché | B33: 0.2 | C33: USD/millón tokens | D33: Precio de lista Anthropic (sept-2026).
A34: Descuento Batch API | B34: 0.5 | C34: % | D34: Procesamiento nocturno por lotes.
A35: Tokens de un PDF de bases | B35: 60000 | C35: tokens | D35: Estimación: ~60 páginas.
A36: Tokens de salida por análisis | B36: 3000 | C36: tokens | D36: Estimación.
A37: Tokens de salida por pregunta | B37: 500 | C37: tokens | D37: Estimación.
A38: Tokens de salida por borrador de oferta | B38: 8000 | C38: tokens | D38: Estimación.
A39: Tokens de entrada filtro diario (por usuario) | B39: 4500 | C39: tokens | D39: Perfil + ~20 licitaciones candidatas.
A40: Tokens de salida filtro diario | B40: 500 | C40: tokens | D40: Estimación.
A41: % de análisis reutilizados entre usuarios | B41: 0.3 | C41: % | D41: Una licitación analizada se sirve a varios usuarios.
A42: Costo por análisis de bases (Sonnet) | B42: =($B$35*$B$31+$B$36*$B$32)/1000000 -> 0.15 | C42: USD
A43: Costo por pregunta (Sonnet + caché) | B43: =($B$35*$B$33+$B$37*$B$32)/1000000 -> 0.017 | C43: USD
A44: Costo por borrador (Sonnet + caché) | B44: =($B$35*$B$33+$B$38*$B$32)/1000000 -> 0.092 | C44: USD
...

Sheet Escenarios
A1: Licita – Escenarios
A2: Edite las celdas azules con fondo amarillo. Cada escenario tiene su propia hoja de proyección y ambos se comparan en Resumen.
A4: Supuesto | B4: Base | C4: Conservador | D4: Nota
A5: Nuevos clientes pagados en el mes 1 | B5: 10 | C5: 5 | D5: Base: piloto exitoso. Conservador: la mitad.
A6: Crecimiento mensual de nuevos clientes | B6: 0.12 | C6: 0.08
A7: Fuga mensual de clientes (churn) | B7: 0.04 | C7: 0.06 | D7: SaaS pyme típico 3–7%. Conservador: venta estacional al Estado.
A8: Mezcla: % Pyme | B8: 0.75 | C8: 0.8
A9: Mezcla: % Pro | B9: 0.2 | C9: 0.16
A10: Mezcla: % Consultoras | B10: =1-B8-B9 -> 0.05 | C10: =1-C8-C9 -> 0.04 | D10: Resto hasta 100%.
A11: % de clientes que paga anual | B11: 0.25 | C11: 0.15 | D11: El ingreso anual se prorratea mes a mes (devengado).
A12: Costo de adquisición por cliente nuevo (CAC) | B12: 25000 | C12: 40000 | D12: Publicidad, contenido, webinars. Conservador: canales más caros.
A13: Factor de ingreso por pago anual (calculado) | B13: =1-B11*Supuestos!$B$16 -> 0.975 | C13: =1-C11*Supuestos!$B$16 -> 0.985 | D13: 1 − % anual × descuento anual (hoja Supuestos).

Sheet Proyección Base
A1: Licita – Proyección mensual a 24 meses – Escenario Base (CLP, sin IVA)
A2: Todas las celdas son fórmulas vinculadas a Supuestos y Escenarios. No editar aquí. Ingresos devengados (pagos anuales prorrateados).
A4: Mes | C4: 1 | D4: 2 | E4: 3 | F4: 4 | G4: 5 | H4: 6 | I4: 7 | J4: 8 | K4: 9 | L4: 10 | M4: 11 | N4: 12 | O4: 13 | P4: 14 | Q4: 15 | R4: 16 | S4: 17 | T4: 18 | U4: 19 | V4: 20 | W4: 21 | X4: 22 | Y4: 23 | Z4: 24
A5: Año | C5: ="Año "&ROUNDUP(C4/12,0) -> Año 1 | D5: ="Año "&ROUNDUP(D4/12,0) -> Año 1 | E5: ="Año "&ROUNDUP(E4/12,0) -> Año 1 | F5: ="Año "&ROUNDUP(F4/12,0) -> Año 1 | G5: ="Año "&ROUNDUP(G4/12,0) -> Año 1 | H5: ="Año "&ROUNDUP(H4/12,0) -> Año 1 | I5: ="Año "&ROUNDUP(I4/12,0) -> Año 1 | J5: ="Año "&ROUNDUP(J4/12,0) -> Año 1 | ... Z5: ="Año "&ROUNDUP(Z4/12,0) -> Año 2
A7: Clientes
A8: Nuevos clientes pagados | C8: =Escenarios!$B$5*(1+Escenarios!$B$6)^(C$4-1) -> 10 | D8: =Escenarios!$B$5*(1+Escenarios!$B$6)^(D$4-1) -> 11.2 | E8: =Escenarios!$B$5*(1+Escenarios!$B$6)^(E$4-1) -> 12.544 | F8: =Escenarios!$B$5*(1+Escenarios!$B$6)^(F$4-1) -> 14.04928 | G8: =Escenarios!$B$5*(1+Escenarios!$B$6)^(G$4-1) -> 15.735194 | H8: =Escenarios!$B$5*(1+Escenarios!$B$6)^(H$4-1) -> 17.623417 | I8: =Escenarios!$B$5*(1+Escenarios!$B$6)^(I$4-1) -> 19.738227 | J8: =Escenarios!$B$5*(1+Escenarios!$B$6)^(J$4-1) -> 22.106814 | ... Z8: =Escenarios!$B$5*(1+Escenarios!$B$6)^(Z$4-1) -> 135.52347
A9: Clientes activos (total) | C9: =C8 -> 10 | D9: =C9*(1-Escenarios!$B$7)+D8 -> 20.8 | E9: =D9*(1-Escenarios!$B$7)+E8 -> 32.512 | F9: =E9*(1-Escenarios!$B$7)+F8 -> 45.2608 | G9: =F9*(1-Escenarios!$B$7)+G8 -> 59.185562 | H9: =G9*(1-Escenarios!$B$7)+H8 -> 74.441556 | I9: =H9*(1-Escenarios!$B$7)+I8 -> 91.202121 | J9: =I9*(1-Escenarios!$B$7)+J8 -> 109.66085 | K9: =J9*(1-Escenarios!$B$7)+K8 -> 130.03405 | ... Z9: =Y9*(1-Escenarios!$B$7)+Z8 -> 925.20098
A10: Pyme | C10: =C9*Escenarios!$B$8 -> 7.5 | D10: =D9*Escenarios!$B$8 -> 15.6 | E10: =E9*Escenarios!$B$8 -> 24.384 | F10: =F9*Escenarios!$B$8 -> 33.9456 | G10: =G9*Escenarios!$B$8 -> 44.389171 | H10: =H9*Escenarios!$B$8 -> 55.831167 | I10: =I9*Escenarios!$B$8 -> 68.40159 | J10: =J9*Escenarios!$B$8 -> 82.245637 | ... Z10: =Z9*Escenarios!$B$8 -> 693.90074
A11: Pro (total) | C11: =C9*Escenarios!$B$9 -> 2 | D11: =D9*Escenarios!$B$9 -> 4.16 | E11: =E9*Escenarios!$B$9 -> 6.5024 | F11: =F9*Escenarios!$B$9 -> 9.05216 | G11: =G9*Escenarios!$B$9 -> 11.837112 | H11: =H9*Escenarios!$B$9 -> 14.888311 | I11: =I9*Escenarios!$B$9 -> 18.240424 | J11: =J9*Escenarios!$B$9 -> 21.93217 | ... Z11: =Z9*Escenarios!$B$9 -> 185.0402
A12: Pro a precio fundador | C12: =MIN(C11,Supuestos!$B$13) -> 2 | D12: =MIN(D11,Supuestos!$B$13) -> 4.16 | E12: =MIN(E11,Supuestos!$B$13) -> 6.5024 | F12: =MIN(F11,Supuestos!$B$13) -> 9.05216 | G12: =MIN(G11,Supuestos!$B$13) -> 11.837112 | H12: =MIN(H11,Supuestos!$B$13) -> 14.888311 | I12: =MIN(I11,Supuestos!$B$13) -> 18.240424 | J12: =MIN(J11,Supuestos!$B$13) -> 21.93217 | ... Z12: =MIN(Z11,Supuestos!$B$13) -> 100
A13: Pro a precio regular | C13: =C11-C12 -> 0 | D13: =D11-D12 -> 0 | E13: =E11-E12 -> 0 | F13: =F11-F12 -> 0 | G13: =G11-G12 -> 0 | H13: =H11-H12 -> 0 | I13: =I11-I12 -> 0 | J13: =J11-J12 -> 0 | ... Z13: =Z11-Z12 -> 85.040196
A14: Consultoras | C14: =C9*Escenarios!$B$10 -> 0.5 | D14: =D9*Escenarios!$B$10 -> 1.04 | E14: =E9*Escenarios!$B$10 -> 1.6256 | F14: =F9*Escenarios!$B$10 -> 2.26304 | G14: =G9*Escenarios!$B$10 -> 2.9592781 | H14: =H9*Escenarios!$B$10 -> 3.7220778 | I14: =I9*Escenarios!$B$10 -> 4.560106 | J14: =J9*Escenarios!$B$10 -> 5.4830425 | ... Z14: =Z9*Escenarios!$B$10 -> 46.260049
A15: Empresas gestionadas por consultoras | C15: =C14*Supuestos!$B$15 -> 3 | D15: =D14*Supuestos!$B$15 -> 6.24 | E15: =E14*Supuestos!$B$15 -> 9.7536 | F15: =F14*Supuestos!$B$15 -> 13.57824 | G15: =G14*Supuestos!$B$15 -> 17.755668 | H15: =H14*Supuestos!$B$15 -> 22.332467 | I15: =I14*Supuestos!$B$15 -> 27.360636 | J15: =J14*Supuestos!$B$15 -> 32.898255 | ... Z15: =Z14*Supuestos!$B$15 -> 277.56029
A17: Ingresos netos (sin IVA)
A18: Ingresos Pyme | C18: =C10*Supuestos!$B$20*Escenarios!$B$13 -> 122837.71 | D18: =D10*Supuestos!$B$20*Escenarios!$B$13 -> 255502.44 | E18: =E10*Supuestos!$B$20*Escenarios!$B$13 -> 399369.96 | F18: =F10*Supuestos!$B$20*Escenarios!$B$13 -> 555973.3 | G18: =G10*Supuestos!$B$20*Escenarios!$B$13 -> 727021.89 | H18: =H10*Supuestos!$B$20*Escenarios!$B$13 -> 914423.03 | I18: =I10*Supuestos!$B$20*Escenarios!$B$13 -> 1120306 | J18: =J10*Supuestos!$B$20*Escenarios!$B$13 -> 1347048.8 | ... Z18: =Z10*Supuestos!$B$20*Escenarios!$B$13 -> 11364957
A19: Ingresos Pro fundador | C19: =C12*Supuestos!$B$22*Escenarios!$B$13 -> 65529.832 | D19: =D12*Supuestos!$B$22*Escenarios!$B$13 -> 136302.05 | E19: =E12*Supuestos!$B$22*Escenarios!$B$13 -> 213050.59 | F19: =F12*Supuestos!$B$22*Escenarios!$B$13 -> 296593.26 | G19: =G12*Supuestos!$B$22*Escenarios!$B$13 -> 387841.99 | H19: =H12*Supuestos!$B$22*Escenarios!$B$13 -> 487814.27 | I19: =I12*Supuestos!$B$22*Escenarios!$B$13 -> 597645.96 | J19: =J12*Supuestos!$B$22*Escenarios!$B$13 -> 718605.71 | ... Z19: =Z12*Supuestos!$B$22*Escenarios!$B$13 -> 3276491.6
A20: Ingresos Pro regular | C20: =C13*Supuestos!$B$21*Escenarios!$B$13 -> 0 | D20: =D13*Supuestos!$B$21*Escenarios!$B$13 -> 0 | E20: =E13*Supuestos!$B$21*Escenarios!$B$13 -> 0 | F20: =F13*Supuestos!$B$21*Escenarios!$B$13 -> 0 | G20: =G13*Supuestos!$B$21*Escenarios!$B$13 -> 0 | H20: =H13*Supuestos!$B$21*Escenarios!$B$13 -> 0 | I20: =I13*Supuestos!$B$21*Escenarios!$B$13 -> 0 | J20: =J13*Supuestos!$B$21*Escenarios!$B$13 -> 0 | ... Z20: =Z13*Supuestos!$B$21*Escenarios!$B$13 -> 4179850.7
A21: Ingresos Consultoras | C21: =C15*Supuestos!$B$23*Escenarios!$B$13 -> 73714.916 | D21: =D15*Supuestos!$B$23*Escenarios!$B$13 -> 153327.03 | E21: =E15*Supuestos!$B$23*Escenarios!$B$13 -> 239661.93 | F21: =F15*Supuestos!$B$23*Escenarios!$B$13 -> 333639.61 | G21: =G15*Supuestos!$B$23*Escenarios!$B$13 -> 436285.87 | H21: =H15*Supuestos!$B$23*Escenarios!$B$13 -> 548745.3 | I21: =I15*Supuestos!$B$23*Escenarios!$B$13 -> 672295.67 | J21: =J15*Supuestos!$B$23*Escenarios!$B$13 -> 808364.03 | ... Z21: =Z15*Supuestos!$B$23*Escenarios!$B$13 -> 6820111.3
A22: Total ingresos (MRR neto) | C22: =SUM(C18:C21) -> 262082.46 | D22: =SUM(D18:D21) -> 545131.51 | E22: =SUM(E18:E21) -> 852082.49 | F22: =SUM(F18:F21) -> 1186206.2 | G22: =SUM(G18:G21) -> 1551149.7 | H22: =SUM(H18:H21) -> 1950982.6 | I22: =SUM(I18:I21) -> 2390247.6 | J22: =SUM(J18:J21) -> 2874018.5 | ... Z22: =SUM(Z18:Z21) -> 25641411
A24: Costos variables
A25: IA por usuario (análisis, preguntas, borradores, filtro) | C25: =C10*Supuestos!$B$51+(C11+C15)*Supuestos!$B$52 -> 33582.5 | D25: =D10*Supuestos!$B$51+(D11+D15)*Supuestos!$B$52 -> 69851.6 | E25: =E10*Supuestos!$B$51+(E11+E15)*Supuestos!$B$52 -> 109183.42 | F25: =F10*Supuestos!$B$51+(F11+F15)*Supuestos!$B$52 -> 151997.08 | G25: =G10*Supuestos!$B$51+(G11+G15)*Supuestos!$B$52 -> 198759.91 | H25: =H10*Supuestos!$B$51+(H11+H15)*Supuestos!$B$52 -> 249993.36 | I25: =I10*Supuestos!$B$51+(I11+I15)*Supuestos!$B$52 -> 306279.52 | J25: =J10*Supuestos!$B$51+(J11+J15)*Supuestos!$B$52 -> 368268.55 | ... Z25: =Z10*Supuestos!$B$51+(Z11+Z15)*Supuestos!$B$52 -> 3107056.2
A26: WhatsApp | C26: =C10*Supuestos!$B$58+(C11+C15)*Supuestos!$B$59 -> 7125 | D26: =D10*Supuestos!$B$58+(D11+D15)*Supuestos!$B$59 -> 14820 | E26: =E10*Supuestos!$B$58+(E11+E15)*Supuestos!$B$59 -> 23164.8 | F26: =F10*Supuestos!$B$58+(F11+F15)*Supuestos!$B$59 -> 32248.32 | G26: =G10*Supuestos!$B$58+(G11+G15)*Supuestos!$B$59 -> 42169.713 | H26: =H10*Supuestos!$B$58+(H11+H15)*Supuestos!$B$59 -> 53039.609 | I26: =I10*Supuestos!$B$58+(I11+I15)*Supuestos!$B$59 -> 64981.511 | J26: =J10*Supuestos!$B$58+(J11+J15)*Supuestos!$B$59 -> 78133.356 | ... Z26: =Z10*Supuestos!$B$58+(Z11+Z15)*Supuestos!$B$59 -> 659205.7
A27: Comisión pasarela de pago | C27: =C22*(1+Supuestos!$B$7)*Supuestos!$B$60 -> 10915.734 | D27: =D22*(1+Supuestos!$B$7)*Supuestos!$B$60 -> 22704.728 | E27: =E22*(1+Supuestos!$B$7)*Supuestos!$B$60 -> 35489.236 | F27: =F22*(1+Supuestos!$B$7)*Supuestos!$B$60 -> 49405.487 | G27: =G22*(1+Supuestos!$B$7)*Supuestos!$B$60 -> 64605.387 | H27: =H22*(1+Supuestos!$B$7)*Supuestos!$B$60 -> 81258.425 | I27: =I22*(1+Supuestos!$B$7)*Supuestos!$B$60 -> 99553.812 | J27: =J22*(1+Supuestos!$B$7)*Supuestos!$B$60 -> 119702.87 | ... Z27: =Z22*(1+Supuestos!$B$7)*Supuestos!$B$60 -> 1067964.7
A28: Total costos variables | C28: =SUM(C25:C27) -> 51623.234 | D28: =SUM(D25:D27) -> 107376.33 | E28: =SUM(E25:E27) -> 167837.46 | F28: =SUM(F25:F27) -> 233650.89 | G28: =SUM(G25:G27) -> 305535.01 | H28: =SUM(H25:H27) -> 384291.39 | I28: =SUM(I25:I27) -> 470814.84 | J28: =SUM(J25:J27) -> 566104.78 | ... Z28: =SUM(Z25:Z27) -> 4834226.6
A29: Margen de contribución | C29: =C22-C28 -> 210459.22 | D29: =D22-D28 -> 437755.19 | E29: =E22-E28 -> 684245.03 | F29: =F22-F28 -> 952555.28 | G29: =G22-G28 -> 1245614.7 | H29: =H22-H28 -> 1566691.2 | I29: =I22-I28 -> 1919432.7 | J29: =J22-J28 -> 2307913.7 | ... Z29: =Z22-Z28 -> 20807184
A30: Margen de contribución % | C30: =IF(C22=0,0,C29/C22) -> 0.80302675 | D30: =IF(D22=0,0,D29/D22) -> 0.80302675 | E30: =IF(E22=0,0,E29/E22) -> 0.80302675 | F30: =IF(F22=0,0,F29/F22) -> 0.80302675 | G30: =IF(G22=0,0,G29/G22) -> 0.80302675 | H30: =IF(H22=0,0,H29/H22) -> 0.80302675 | I30: =IF(I22=0,0,I29/I22) -> 0.80302675 | J30: =IF(J22=0,0,J29/J22) -> 0.80302675 | ... Z30: =IF(Z22=0,0,Z29/Z22) -> 0.81146799
A32: Costos fijos y de estructura
A33: Factor de escala (0 = lanzamiento, 1 = escala) | C33: =MIN(1,C9/Supuestos!$B$63) -> 0.01 | D33: =MIN(1,D9/Supuestos!$B$63) -> 0.0208 | E33: =MIN(1,E9/Supuestos!$B$63) -> 0.032512 | F33: =MIN(1,F9/Supuestos!$B$63) -> 0.0452608 | G33: =MIN(1,G9/Supuestos!$B$63) -> 0.059185562 | H33: =MIN(1,H9/Supuestos!$B$63) -> 0.074441556 | I33: =MIN(1,I9/Supuestos!$B$63) -> 0.091202121 | J33: =MIN(1,J9/Supuestos!$B$63) -> 0.10966085 | ... Z33: =MIN(1,Z9/Supuestos!$B$63) -> 0.92520098
A34: Infraestructura y software | C34: =Supuestos!$B$72+(Supuestos!$B$73-Supuestos!$B$72)*C33 -> 189870 | D34: =Supuestos!$B$72+(Supuestos!$B$73-Supuestos!$B$72)*D33 -> 195021.6 | E34: =Supuestos!$B$72+(Supuestos!$B$73-Supuestos!$B$72)*E33 -> 200608.22 | F34: =Supuestos!$B$72+(Supuestos!$B$73-Supuestos!$B$72)*F33 -> 206689.4 | G34: =Supuestos!$B$72+(Supuestos!$B$73-Supuestos!$B$72)*G33 -> 213331.51 | H34: =Supuestos!$B$72+(Supuestos!$B$73-Supuestos!$B$72)*H33 -> 220608.62 | I34: =Supuestos!$B$72+(Supuestos!$B$73-Supuestos!$B$72)*I33 -> 228603.41 | J34: =Supuestos!$B$72+(Supuestos!$B$73-Supuestos!$B$72)*J33 -> 237408.23 | ... Z34: =Supuestos!$B$72+(Supuestos!$B$73-Supuestos!$B$72)*Z33 -> 626420.87
A35: IA fija (clasificación de licitaciones) | C35: =Supuestos!$B$81 -> 62343.75 | D35: =Supuestos!$B$81 -> 62343.75 | E35: =Supuestos!$B$81 -> 62343.75 | F35: =Supuestos!$B$81 -> 62343.75 | G35: =Supuestos!$B$81 -> 62343.75 | H35: =Supuestos!$B$81 -> 62343.75 | I35: =Supuestos!$B$81 -> 62343.75 | J35: =Supuestos!$B$81 -> 62343.75 | ... Z35: =Supuestos!$B$81 -> 62343.75
A36: Administración (contador, factura electrónica) | C36: =Supuestos!$B$74+(Supuestos!$B$75-Supuestos!$B$74)*C33 -> 121300 | D36: =Supuestos!$B$74+(Supuestos!$B$75-Supuestos!$B$74)*D33 -> 122704 | E36: =Supuestos!$B$74+(Supuestos!$B$75-Supuestos!$B$74)*E33 -> 124226.56 | F36: =Supuestos!$B$74+(Supuestos!$B$75-Supuestos!$B$74)*F33 -> 125883.9 | G36: =Supuestos!$B$74+(Supuestos!$B$75-Supuestos!$B$74)*G33 -> 127694.12 | H36: =Supuestos!$B$74+(Supuestos!$B$75-Supuestos!$B$74)*H33 -> 129677.4 | I36: =Supuestos!$B$74+(Supuestos!$B$75-Supuestos!$B$74)*I33 -> 131856.28 | J36: =Supuestos!$B$74+(Supuestos!$B$75-Supuestos!$B$74)*J33 -> 134255.91 | ... Z36: =Supuestos!$B$74+(Supuestos!$B$75-Supuestos!$B$74)*Z33 -> 240276.13
A37: Marketing (CAC × nuevos clientes) | C37: =C8*Escenarios!$B$12 -> 250000 | D37: =D8*Escenarios!$B$12 -> 280000 | E37: =E8*Escenarios!$B$12 -> 313600 | F37: =F8*Escenarios!$B$12 -> 351232 | G37: =G8*Escenarios!$B$12 -> 393379.84 | H37: =H8*Escenarios!$B$12 -> 440585.42 | I37: =I8*Escenarios!$B$12 -> 493455.67 | J37: =J8*Escenarios!$B$12 -> 552670.35 | ... Z37: =Z8*Escenarios!$B$12 -> 3388086.8
A38: Sueldos / retiro fundadores | C38: =IF(C$4>=Supuestos!$B$85,Supuestos!$B$84,0) -> 0 | D38: =IF(D$4>=Supuestos!$B$85,Supuestos!$B$84,0) -> 0 | E38: =IF(E$4>=Supuestos!$B$85,Supuestos!$B$84,0) -> 0 | F38: =IF(F$4>=Supuestos!$B$85,Supuestos!$B$84,0) -> 0 | G38: =IF(G$4>=Supuestos!$B$85,Supuestos!$B$84,0) -> 0 | H38: =IF(H$4>=Supuestos!$B$85,Supuestos!$B$84,0) -> 0 | I38: =IF(I$4>=Supuestos!$B$85,Supuestos!$B$84,0) -> 1500000 | J38: =IF(J$4>=Supuestos!$B$85,Supuestos!$B$84,0) -> 1500000 | ... Z38: =IF(Z$4>=Supuestos!$B$85,Supuestos!$B$84,0) -> 1500000
A39: Costos únicos (legal) | C39: =IF(C$4=1,Supuestos!$B$86,0) -> 600000 | D39: =IF(D$4=1,Supuestos!$B$86,0) -> 0 | E39: =IF(E$4=1,Supuestos!$B$86,0) -> 0 | F39: =IF(F$4=1,Supuestos!$B$86,0) -> 0 | G39: =IF(G$4=1,Supuestos!$B$86,0) -> 0 | H39: =IF(H$4=1,Supuestos!$B$86,0) -> 0 | I39: =IF(I$4=1,Supuestos!$B$86,0) -> 0 | J39: =IF(J$4=1,Supuestos!$B$86,0) -> 0 | ... Z39: =IF(Z$4=1,Supuestos!$B$86,0) -> 0
A40: Total costos fijos y de estructura | C40: =SUM(C34:C39) -> 1223513.8 | D40: =SUM(D34:D39) -> 660069.35 | E40: =SUM(E34:E39) -> 700778.53 | F40: =SUM(F34:F39) -> 746149.06 | G40: =SUM(G34:G39) -> 796749.23 | H40: =SUM(H34:H39) -> 853215.2 | I40: =SUM(I34:I39) -> 2416259.1 | J40: =SUM(J34:J39) -> 2486678.2 | ... Z40: =SUM(Z34:Z39) -> 5817127.6
A42: Resultado
A43: EBITDA | C43: =C29-C40 -> -1013054.5 | D43: =D29-D40 -> -222314.16 | E43: =E29-E40 -> -16533.506 | F43: =F29-F40 -> 206406.23 | G43: =G29-G40 -> 448865.51 | H43: =H29-H40 -> 713476.01 | I43: =I29-I40 -> -496826.36 | J43: =J29-J40 -> -178764.51 | ... Z43: =Z29-Z40 -> 14990056
A44: Depreciación | C44: =IF(C$4<=Supuestos!$B$88,Supuestos!$B$89,0) -> 50000 | D44: =IF(D$4<=Supuestos!$B$88,Supuestos!$B$89,0) -> 50000 | E44: =IF(E$4<=Supuestos!$B$88,Supuestos!$B$89,0) -> 50000 | F44: =IF(F$4<=Supuestos!$B$88,Supuestos!$B$89,0) -> 50000 | G44: =IF(G$4<=Supuestos!$B$88,Supuestos!$B$89,0) -> 50000 | H44: =IF(H$4<=Supuestos!$B$88,Supuestos!$B$89,0) -> 50000 | I44: =IF(I$4<=Supuestos!$B$88,Supuestos!$B$89,0) -> 50000 | J44: =IF(J$4<=Supuestos!$B$88,Supuestos!$B$89,0) -> 50000 | ... Z44: =IF(Z$4<=Supuestos!$B$88,Supuestos!$B$89,0) -> 50000
A45: Resultado antes de impuestos | C45: =C43-C44 -> -1063054.5 | D45: =D43-D44 -> -272314.16 | E45: =E43-E44 -> -66533.506 | F45: =F43-F44 -> 156406.23 | G45: =G43-G44 -> 398865.51 | H45: =H43-H44 -> 663476.01 | I45: =I43-I44 -> -546826.36 | J45: =J43-J44 -> -228764.51 | ... Z45: =Z43-Z44 -> 14940056
A46: Resultado acumulado | C46: =C45 -> -1063054.5 | D46: =C46+D45 -> -1335368.7 | E46: =D46+E45 -> -1401902.2 | F46: =E46+F45 -> -1245496 | G46: =F46+G45 -> -846630.46 | H46: =G46+H45 -> -183154.45 | I46: =H46+I45 -> -729980.81 | J46: =I46+J45 -> -958745.32 | K46: =J46+K45 -> -837424.06 | ... Z46: =Y46+Z45 -> 86548308
...

Sheet Proyección Conservador
A1: Licita – Proyección mensual a 24 meses – Escenario Conservador (CLP, sin IVA)
A2: Todas las celdas son fórmulas vinculadas a Supuestos y Escenarios. No editar aquí. Ingresos devengados (pagos anuales prorrateados).
A4: Mes | C4: 1 | D4: 2 | E4: 3 | F4: 4 | G4: 5 | H4: 6 | I4: 7 | J4: 8 | K4: 9 | L4: 10 | M4: 11 | N4: 12 | O4: 13 | P4: 14 | Q4: 15 | R4: 16 | S4: 17 | T4: 18 | U4: 19 | V4: 20 | W4: 21 | X4: 22 | Y4: 23 | Z4: 24
A5: Año | C5: ="Año "&ROUNDUP(C4/12,0) -> Año 1 | D5: ="Año "&ROUNDUP(D4/12,0) -> Año 1 | E5: ="Año "&ROUNDUP(E4/12,0) -> Año 1 | F5: ="Año "&ROUNDUP(F4/12,0) -> Año 1 | G5: ="Año "&ROUNDUP(G4/12,0) -> Año 1 | H5: ="Año "&ROUNDUP(H4/12,0) -> Año 1 | I5: ="Año "&ROUNDUP(I4/12,0) -> Año 1 | J5: ="Año "&ROUNDUP(J4/12,0) -> Año 1 | ... Z5: ="Año "&ROUNDUP(Z4/12,0) -> Año 2
A7: Clientes
A8: Nuevos clientes pagados | C8: =Escenarios!$C$5*(1+Escenarios!$C$6)^(C$4-1) -> 5 | D8: =Escenarios!$C$5*(1+Escenarios!$C$6)^(D$4-1) -> 5.4 | E8: =Escenarios!$C$5*(1+Escenarios!$C$6)^(E$4-1) -> 5.832 | F8: =Escenarios!$C$5*(1+Escenarios!$C$6)^(F$4-1) -> 6.29856 | G8: =Escenarios!$C$5*(1+Escenarios!$C$6)^(G$4-1) -> 6.8024448 | H8: =Escenarios!$C$5*(1+Escenarios!$C$6)^(H$4-1) -> 7.3466404 | I8: =Escenarios!$C$5*(1+Escenarios!$C$6)^(I$4-1) -> 7.9343716 | J8: =Escenarios!$C$5*(1+Escenarios!$C$6)^(J$4-1) -> 8.5691213 | ... Z8: =Escenarios!$C$5*(1+Escenarios!$C$6)^(Z$4-1) -> 29.357318
A9: Clientes activos (total) | C9: =C8 -> 5 | D9: =C9*(1-Escenarios!$C$7)+D8 -> 10.1 | E9: =D9*(1-Escenarios!$C$7)+E8 -> 15.326 | F9: =E9*(1-Escenarios!$C$7)+F8 -> 20.705 | G9: =F9*(1-Escenarios!$C$7)+G8 -> 26.265145 | H9: =G9*(1-Escenarios!$C$7)+H8 -> 32.035876 | I9: =H9*(1-Escenarios!$C$7)+I8 -> 38.048096 | J9: =I9*(1-Escenarios!$C$7)+J8 -> 44.334331 | K9: =J9*(1-Escenarios!$C$7)+K8 -> 50.928922 | ... Z9: =Y9*(1-Escenarios!$C$7)+Z8 -> 218.38145
A10: Pyme | C10: =C9*Escenarios!$C$8 -> 4 | D10: =D9*Escenarios!$C$8 -> 8.08 | E10: =E9*Escenarios!$C$8 -> 12.2608 | F10: =F9*Escenarios!$C$8 -> 16.564 | G10: =G9*Escenarios!$C$8 -> 21.012116 | H10: =H9*Escenarios!$C$8 -> 25.628701 | I10: =I9*Escenarios!$C$8 -> 30.438476 | J10: =J9*Escenarios!$C$8 -> 35.467465 | ... Z10: =Z9*Escenarios!$C$8 -> 174.70516
A11: Pro (total) | C11: =C9*Escenarios!$C$9 -> 0.8 | D11: =D9*Escenarios!$C$9 -> 1.616 | E11: =E9*Escenarios!$C$9 -> 2.45216 | F11: =F9*Escenarios!$C$9 -> 3.3128 | G11: =G9*Escenarios!$C$9 -> 4.2024232 | H11: =H9*Escenarios!$C$9 -> 5.1257402 | I11: =I9*Escenarios!$C$9 -> 6.0876953 | J11: =J9*Escenarios!$C$9 -> 7.093493 | ... Z11: =Z9*Escenarios!$C$9 -> 34.941032
A12: Pro a precio fundador | C12: =MIN(C11,Supuestos!$B$13) -> 0.8 | D12: =MIN(D11,Supuestos!$B$13) -> 1.616 | E12: =MIN(E11,Supuestos!$B$13) -> 2.45216 | F12: =MIN(F11,Supuestos!$B$13) -> 3.3128 | G12: =MIN(G11,Supuestos!$B$13) -> 4.2024232 | H12: =MIN(H11,Supuestos!$B$13) -> 5.1257402 | I12: =MIN(I11,Supuestos!$B$13) -> 6.0876953 | J12: =MIN(J11,Supuestos!$B$13) -> 7.093493 | ... Z12: =MIN(Z11,Supuestos!$B$13) -> 34.941032
A13: Pro a precio regular | C13: =C11-C12 -> 0 | D13: =D11-D12 -> 0 | E13: =E11-E12 -> 0 | F13: =F11-F12 -> 0 | G13: =G11-G12 -> 0 | H13: =H11-H12 -> 0 | I13: =I11-I12 -> 0 | J13: =J11-J12 -> 0 | ... Z13: =Z11-Z12 -> 0
A14: Consultoras | C14: =C9*Escenarios!$C$10 -> 0.2 | D14: =D9*Escenarios!$C$10 -> 0.404 | E14: =E9*Escenarios!$C$10 -> 0.61304 | F14: =F9*Escenarios!$C$10 -> 0.8282 | G14: =G9*Escenarios!$C$10 -> 1.0506058 | H14: =H9*Escenarios!$C$10 -> 1.2814351 | I14: =I9*Escenarios!$C$10 -> 1.5219238 | J14: =J9*Escenarios!$C$10 -> 1.7733732 | ... Z14: =Z9*Escenarios!$C$10 -> 8.735258
A15: Empresas gestionadas por consultoras | C15: =C14*Supuestos!$B$15 -> 1.2 | D15: =D14*Supuestos!$B$15 -> 2.424 | E15: =E14*Supuestos!$B$15 -> 3.67824 | F15: =F14*Supuestos!$B$15 -> 4.9692 | G15: =G14*Supuestos!$B$15 -> 6.3036348 | H15: =H14*Supuestos!$B$15 -> 7.6886104 | I15: =I14*Supuestos!$B$15 -> 9.1315429 | J15: =J14*Supuestos!$B$15 -> 10.640239 | ... Z15: =Z14*Supuestos!$B$15 -> 52.411548
A17: Ingresos netos (sin IVA)
A18: Ingresos Pyme | C18: =C10*Supuestos!$B$20*Escenarios!$C$13 -> 66185.378 | D18: =D10*Supuestos!$B$20*Escenarios!$C$13 -> 133694.46 | E18: =E10*Supuestos!$B$20*Escenarios!$C$13 -> 202871.42 | F18: =F10*Supuestos!$B$20*Escenarios!$C$13 -> 274073.65 | G18: =G10*Supuestos!$B$20*Escenarios!$C$13 -> 347673.71 | H18: =H10*Supuestos!$B$20*Escenarios!$C$13 -> 424061.32 | I18: =I10*Supuestos!$B$20*Escenarios!$C$13 -> 503645.52 | J18: =J10*Supuestos!$B$20*Escenarios!$C$13 -> 586856.89 | ... Z18: =Z10*Supuestos!$B$20*Escenarios!$C$13 -> 2890731.8
A19: Ingresos Pro fundador | C19: =C12*Supuestos!$B$22*Escenarios!$C$13 -> 26480.773 | D19: =D12*Supuestos!$B$22*Escenarios!$C$13 -> 53491.162 | E19: =E12*Supuestos!$B$22*Escenarios!$C$13 -> 81168.866 | F19: =F12*Supuestos!$B$22*Escenarios!$C$13 -> 109656.88 | G19: =G12*Supuestos!$B$22*Escenarios!$C$13 -> 139104.27 | H19: =H12*Supuestos!$B$22*Escenarios!$C$13 -> 169666.96 | I19: =I12*Supuestos!$B$22*Escenarios!$C$13 -> 201508.6 | J19: =J12*Supuestos!$B$22*Escenarios!$C$13 -> 234801.47 | ... Z19: =Z12*Supuestos!$B$22*Escenarios!$C$13 -> 1156581.9
A20: Ingresos Pro regular | C20: =C13*Supuestos!$B$21*Escenarios!$C$13 -> 0 | D20: =D13*Supuestos!$B$21*Escenarios!$C$13 -> 0 | E20: =E13*Supuestos!$B$21*Escenarios!$C$13 -> 0 | F20: =F13*Supuestos!$B$21*Escenarios!$C$13 -> 0 | G20: =G13*Supuestos!$B$21*Escenarios!$C$13 -> 0 | H20: =H13*Supuestos!$B$21*Escenarios!$C$13 -> 0 | I20: =I13*Supuestos!$B$21*Escenarios!$C$13 -> 0 | J20: =J13*Supuestos!$B$21*Escenarios!$C$13 -> 0 | ... Z20: =Z13*Supuestos!$B$21*Escenarios!$C$13 -> 0
A21: Ingresos Consultoras | C21: =C15*Supuestos!$B$23*Escenarios!$C$13 -> 29788.387 | D21: =D15*Supuestos!$B$23*Escenarios!$C$13 -> 60172.541 | E21: =E15*Supuestos!$B$23*Escenarios!$C$13 -> 91307.362 | F21: =F15*Supuestos!$B$23*Escenarios!$C$13 -> 123353.71 | G21: =G15*Supuestos!$B$23*Escenarios!$C$13 -> 156479.26 | H21: =H15*Supuestos!$B$23*Escenarios!$C$13 -> 190859.41 | I21: =I15*Supuestos!$B$23*Escenarios!$C$13 -> 226678.28 | J21: =J15*Supuestos!$B$23*Escenarios!$C$13 -> 264129.64 | ... Z21: =Z15*Supuestos!$B$23*Escenarios!$C$13 -> 1301046.2
A22: Total ingresos (MRR neto) | C22: =SUM(C18:C21) -> 122454.54 | D22: =SUM(D18:D21) -> 247358.17 | E22: =SUM(E18:E21) -> 375347.65 | F22: =SUM(F18:F21) -> 507084.24 | G22: =SUM(G18:G21) -> 643257.23 | H22: =SUM(H18:H21) -> 784587.69 | I22: =SUM(I18:I21) -> 931832.39 | J22: =SUM(J18:J21) -> 1085788 | ... Z22: =SUM(Z18:Z21) -> 5348359.9
A24: Costos variables
A25: IA por usuario (análisis, preguntas, borradores, filtro) | C25: =C10*Supuestos!$B$51+(C11+C15)*Supuestos!$B$52 -> 14953 | D25: =D10*Supuestos!$B$51+(D11+D15)*Supuestos!$B$52 -> 30205.06 | E25: =E10*Supuestos!$B$51+(E11+E15)*Supuestos!$B$52 -> 45833.936 | F25: =F10*Supuestos!$B$51+(F11+F15)*Supuestos!$B$52 -> 61920.373 | G25: =G10*Supuestos!$B$51+(G11+G15)*Supuestos!$B$52 -> 78548.542 | H25: =H10*Supuestos!$B$51+(H11+H15)*Supuestos!$B$52 -> 95806.492 | I25: =I10*Supuestos!$B$51+(I11+I15)*Supuestos!$B$52 -> 113786.63 | J25: =J10*Supuestos!$B$51+(J11+J15)*Supuestos!$B$52 -> 132586.25 | ... Z25: =Z10*Supuestos!$B$51+(Z11+Z15)*Supuestos!$B$52 -> 653091.56
A26: WhatsApp | C26: =C10*Supuestos!$B$58+(C11+C15)*Supuestos!$B$59 -> 3268 | D26: =D10*Supuestos!$B$58+(D11+D15)*Supuestos!$B$59 -> 6601.36 | E26: =E10*Supuestos!$B$58+(E11+E15)*Supuestos!$B$59 -> 10017.074 | F26: =F10*Supuestos!$B$58+(F11+F15)*Supuestos!$B$59 -> 13532.788 | G26: =G10*Supuestos!$B$58+(G11+G15)*Supuestos!$B$59 -> 17166.899 | H26: =H10*Supuestos!$B$58+(H11+H15)*Supuestos!$B$59 -> 20938.649 | I26: =I10*Supuestos!$B$58+(I11+I15)*Supuestos!$B$59 -> 24868.235 | J26: =J10*Supuestos!$B$58+(J11+J15)*Supuestos!$B$59 -> 28976.919 | ... Z26: =Z10*Supuestos!$B$58+(Z11+Z15)*Supuestos!$B$59 -> 142734.12
A27: Comisión pasarela de pago | C27: =C22*(1+Supuestos!$B$7)*Supuestos!$B$60 -> 5100.2315 | D27: =D22*(1+Supuestos!$B$7)*Supuestos!$B$60 -> 10302.468 | E27: =E22*(1+Supuestos!$B$7)*Supuestos!$B$60 -> 15633.23 | F27: =F22*(1+Supuestos!$B$7)*Supuestos!$B$60 -> 21120.059 | G27: =G22*(1+Supuestos!$B$7)*Supuestos!$B$60 -> 26791.664 | H27: =H22*(1+Supuestos!$B$7)*Supuestos!$B$60 -> 32678.077 | I27: =I22*(1+Supuestos!$B$7)*Supuestos!$B$60 -> 38810.819 | J27: =J22*(1+Supuestos!$B$7)*Supuestos!$B$60 -> 45223.07 | ... Z27: =Z22*(1+Supuestos!$B$7)*Supuestos!$B$60 -> 222759.19
A28: Total costos variables | C28: =SUM(C25:C27) -> 23321.232 | D28: =SUM(D25:D27) -> 47108.888 | E28: =SUM(E25:E27) -> 71484.239 | F28: =SUM(F25:F27) -> 96573.22 | G28: =SUM(G25:G27) -> 122507.1 | H28: =SUM(H25:H27) -> 149423.22 | I28: =SUM(I25:I27) -> 177465.69 | J28: =SUM(J25:J27) -> 206786.24 | ... Z28: =SUM(Z25:Z27) -> 1018584.9
A29: Margen de contribución | C29: =C22-C28 -> 99133.306 | D29: =D22-D28 -> 200249.28 | E29: =E22-E28 -> 303863.41 | F29: =F22-F28 -> 410511.02 | G29: =G22-G28 -> 520750.13 | H29: =H22-H28 -> 635164.47 | I29: =I22-I28 -> 754366.7 | J29: =J22-J28 -> 879001.77 | ... Z29: =Z22-Z28 -> 4329775
A30: Margen de contribución % | C30: =IF(C22=0,0,C29/C22) -> 0.80955192 | D30: =IF(D22=0,0,D29/D22) -> 0.80955192 | E30: =IF(E22=0,0,E29/E22) -> 0.80955192 | F30: =IF(F22=0,0,F29/F22) -> 0.80955192 | G30: =IF(G22=0,0,G29/G22) -> 0.80955192 | H30: =IF(H22=0,0,H29/H22) -> 0.80955192 | I30: =IF(I22=0,0,I29/I22) -> 0.80955192 | J30: =IF(J22=0,0,J29/J22) -> 0.80955192 | ... Z30: =IF(Z22=0,0,Z29/Z22) -> 0.80955192
A32: Costos fijos y de estructura
A33: Factor de escala (0 = lanzamiento, 1 = escala) | C33: =MIN(1,C9/Supuestos!$B$63) -> 0.005 | D33: =MIN(1,D9/Supuestos!$B$63) -> 0.0101 | E33: =MIN(1,E9/Supuestos!$B$63) -> 0.015326 | F33: =MIN(1,F9/Supuestos!$B$63) -> 0.020705 | G33: =MIN(1,G9/Supuestos!$B$63) -> 0.026265145 | H33: =MIN(1,H9/Supuestos!$B$63) -> 0.032035876 | I33: =MIN(1,I9/Supuestos!$B$63) -> 0.038048096 | J33: =MIN(1,J9/Supuestos!$B$63) -> 0.044334331 | ... Z33: =MIN(1,Z9/Supuestos!$B$63) -> 0.21838145
A34: Infraestructura y software | C34: =Supuestos!$B$72+(Supuestos!$B$73-Supuestos!$B$72)*C33 -> 187485 | D34: =Supuestos!$B$72+(Supuestos!$B$73-Supuestos!$B$72)*D33 -> 189917.7 | E34: =Supuestos!$B$72+(Supuestos!$B$73-Supuestos!$B$72)*E33 -> 192410.5 | F34: =Supuestos!$B$72+(Supuestos!$B$73-Supuestos!$B$72)*F33 -> 194976.29 | G34: =Supuestos!$B$72+(Supuestos!$B$73-Supuestos!$B$72)*G33 -> 197628.47 | H34: =Supuestos!$B$72+(Supuestos!$B$73-Supuestos!$B$72)*H33 -> 200381.11 | I34: =Supuestos!$B$72+(Supuestos!$B$73-Supuestos!$B$72)*I33 -> 203248.94 | J34: =Supuestos!$B$72+(Supuestos!$B$73-Supuestos!$B$72)*J33 -> 206247.48 | ... Z34: =Supuestos!$B$72+(Supuestos!$B$73-Supuestos!$B$72)*Z33 -> 289267.95
A35: IA fija (clasificación de licitaciones) | C35: =Supuestos!$B$81 -> 62343.75 | D35: =Supuestos!$B$81 -> 62343.75 | E35: =Supuestos!$B$81 -> 62343.75 | F35: =Supuestos!$B$81 -> 62343.75 | G35: =Supuestos!$B$81 -> 62343.75 | H35: =Supuestos!$B$81 -> 62343.75 | I35: =Supuestos!$B$81 -> 62343.75 | J35: =Supuestos!$B$81 -> 62343.75 | ... Z35: =Supuestos!$B$81 -> 62343.75
A36: Administración (contador, factura electrónica) | C36: =Supuestos!$B$74+(Supuestos!$B$75-Supuestos!$B$74)*C33 -> 120650 | D36: =Supuestos!$B$74+(Supuestos!$B$75-Supuestos!$B$74)*D33 -> 121313 | E36: =Supuestos!$B$74+(Supuestos!$B$75-Supuestos!$B$74)*E33 -> 121992.38 | F36: =Supuestos!$B$74+(Supuestos!$B$75-Supuestos!$B$74)*F33 -> 122691.65 | G36: =Supuestos!$B$74+(Supuestos!$B$75-Supuestos!$B$74)*G33 -> 123414.47 | H36: =Supuestos!$B$74+(Supuestos!$B$75-Supuestos!$B$74)*H33 -> 124164.66 | I36: =Supuestos!$B$74+(Supuestos!$B$75-Supuestos!$B$74)*I33 -> 124946.25 | J36: =Supuestos!$B$74+(Supuestos!$B$75-Supuestos!$B$74)*J33 -> 125763.46 | ... Z36: =Supuestos!$B$74+(Supuestos!$B$75-Supuestos!$B$74)*Z33 -> 148389.59
A37: Marketing (CAC × nuevos clientes) | C37: =C8*Escenarios!$C$12 -> 200000 | D37: =D8*Escenarios!$C$12 -> 216000 | E37: =E8*Escenarios!$C$12 -> 233280 | F37: =F8*Escenarios!$C$12 -> 251942.4 | G37: =G8*Escenarios!$C$12 -> 272097.79 | H37: =H8*Escenarios!$C$12 -> 293865.62 | I37: =I8*Escenarios!$C$12 -> 317374.86 | J37: =J8*Escenarios!$C$12 -> 342764.85 | ... Z37: =Z8*Escenarios!$C$12 -> 1174292.7
A38: Sueldos / retiro fundadores | C38: =IF(C$4>=Supuestos!$B$85,Supuestos!$B$84,0) -> 0 | D38: =IF(D$4>=Supuestos!$B$85,Supuestos!$B$84,0) -> 0 | E38: =IF(E$4>=Supuestos!$B$85,Supuestos!$B$84,0) -> 0 | F38: =IF(F$4>=Supuestos!$B$85,Supuestos!$B$84,0) -> 0 | G38: =IF(G$4>=Supuestos!$B$85,Supuestos!$B$84,0) -> 0 | H38: =IF(H$4>=Supuestos!$B$85,Supuestos!$B$84,0) -> 0 | I38: =IF(I$4>=Supuestos!$B$85,Supuestos!$B$84,0) -> 1500000 | J38: =IF(J$4>=Supuestos!$B$85,Supuestos!$B$84,0) -> 1500000 | ... Z38: =IF(Z$4>=Supuestos!$B$85,Supuestos!$B$84,0) -> 1500000
A39: Costos únicos (legal) | C39: =IF(C$4=1,Supuestos!$B$86,0) -> 600000 | D39: =IF(D$4=1,Supuestos!$B$86,0) -> 0 | E39: =IF(E$4=1,Supuestos!$B$86,0) -> 0 | F39: =IF(F$4=1,Supuestos!$B$86,0) -> 0 | G39: =IF(G$4=1,Supuestos!$B$86,0) -> 0 | H39: =IF(H$4=1,Supuestos!$B$86,0) -> 0 | I39: =IF(I$4=1,Supuestos!$B$86,0) -> 0 | J39: =IF(J$4=1,Supuestos!$B$86,0) -> 0 | ... Z39: =IF(Z$4=1,Supuestos!$B$86,0) -> 0
A40: Total costos fijos y de estructura | C40: =SUM(C34:C39) -> 1170478.8 | D40: =SUM(D34:D39) -> 589574.45 | E40: =SUM(E34:E39) -> 610026.63 | F40: =SUM(F34:F39) -> 631954.08 | G40: =SUM(G34:G39) -> 655484.48 | H40: =SUM(H34:H39) -> 680755.14 | I40: =SUM(I34:I39) -> 2207913.8 | J40: =SUM(J34:J39) -> 2237119.5 | ... Z40: =SUM(Z34:Z39) -> 3174294
A42: Resultado
A43: EBITDA | C43: =C29-C40 -> -1071345.4 | D43: =D29-D40 -> -389325.17 | E43: =E29-E40 -> -306163.22 | F43: =F29-F40 -> -221443.06 | G43: =G29-G40 -> -134734.36 | H43: =H29-H40 -> -45590.671 | I43: =I29-I40 -> -1453547.1 | J43: =J29-J40 -> -1358117.8 | ... Z43: =Z29-Z40 -> 1155481
A44: Depreciación | C44: =IF(C$4<=Supuestos!$B$88,Supuestos!$B$89,0) -> 50000 | D44: =IF(D$4<=Supuestos!$B$88,Supuestos!$B$89,0) -> 50000 | E44: =IF(E$4<=Supuestos!$B$88,Supuestos!$B$89,0) -> 50000 | F44: =IF(F$4<=Supuestos!$B$88,Supuestos!$B$89,0) -> 50000 | G44: =IF(G$4<=Supuestos!$B$88,Supuestos!$B$89,0) -> 50000 | H44: =IF(H$4<=Supuestos!$B$88,Supuestos!$B$89,0) -> 50000 | I44: =IF(I$4<=Supuestos!$B$88,Supuestos!$B$89,0) -> 50000 | J44: =IF(J$4<=Supuestos!$B$88,Supuestos!$B$89,0) -> 50000 | ... Z44: =IF(Z$4<=Supuestos!$B$88,Supuestos!$B$89,0) -> 50000
A45: Resultado antes de impuestos | C45: =C43-C44 -> -1121345.4 | D45: =D43-D44 -> -439325.17 | E45: =E43-E44 -> -356163.22 | F45: =F43-F44 -> -271443.06 | G45: =G43-G44 -> -184734.36 | H45: =H43-H44 -> -95590.671 | I45: =I43-I44 -> -1503547.1 | J45: =J43-J44 -> -1408117.8 | ... Z45: =Z43-Z44 -> 1105481
A46: Resultado acumulado | C46: =C45 -> -1121345.4 | D46: =C46+D45 -> -1560670.6 | E46: =D46+E45 -> -1916833.8 | F46: =E46+F45 -> -2188276.9 | G46: =F46+G45 -> -2373011.3 | H46: =G46+H45 -> -2468601.9 | I46: =H46+I45 -> -3972149 | J46: =I46+J45 -> -5380266.8 | K46: =J46+K45 -> -6689060 | ... Z46: =Y46+Z45 -> -9795004.5
...
